<?xml version="1.0" ?>
<!-- =================================================================================== -->
<!-- |    This document was autogenerated by xacro from lbr_iiwa_14_r820.xacro         | -->
<!-- |    EDITING THIS FILE BY HAND IS NOT RECOMMENDED                                 | -->
<!-- =================================================================================== -->
<robot name="kuka_lbr_iiwa_14_r820" xmlns:xacro="http://wiki.ros.org/xacro">
  <!-- link list -->
  <link name="base_link">
    <visual>
      <origin rpy="0 0 0" xyz="0 0 0"/>
      <geometry>
        <mesh filename="C:/dev/threepp/build/_deps/threepp_data-src/urdf/lbr_iiwa_14_r820/visual/base_link.dae"/>
      </geometry>
    </visual>
    <collision><origin rpy="0 0 0" xyz="-0.007265 0.000030 0.078750"/><geometry><box size="0.257471 0.242590 0.157500"/></geometry></collision>
  </link>
  <link name="link_1">
    <visual>
      <origin rpy="0 0 0" xyz="0 0 0"/>
      <geometry>
        <mesh filename="C:/dev/threepp/build/_deps/threepp_data-src/urdf/lbr_iiwa_14_r820/visual/link_1.dae"/>
      </geometry>
    </visual>
    <collision><origin rpy="0 0 0" xyz="-0.000100 -0.014686 0.296207"/><geometry><box size="0.171682 0.202325 0.297430"/></geometry></collision>
  </link>
  <link name="link_2">
    <visual>
      <origin rpy="0 0 0" xyz="0 0 0"/>
      <geometry>
        <mesh filename="C:/dev/threepp/build/_deps/threepp_data-src/urdf/lbr_iiwa_14_r820/visual/link_2.dae"/>
      </geometry>
    </visual>
    <collision><origin rpy="0 0 0" xyz="-0.000028 0.032194 0.059714"/><geometry><box size="0.171320 0.199618 0.289575"/></geometry></collision>
  </link>
  <link name="link_3">
    <visual>
      <origin rpy="0 0 0" xyz="0 0 0"/>
      <geometry>
        <mesh filename="C:/dev/threepp/build/_deps/threepp_data-src/urdf/lbr_iiwa_14_r820/visual/link_3.dae"/>
      </geometry>
    </visual>
    <collision><origin rpy="0 0 0" xyz="-0.000008 0.023336 0.341069"/><geometry><box size="0.136049 0.182662 0.293272"/></geometry></collision>
  </link>
  <link name="link_4">
    <visual>
      <origin rpy="0 0 0" xyz="0 0 0"/>
      <geometry>
        <mesh filename="C:/dev/threepp/build/_deps/threepp_data-src/urdf/lbr_iiwa_14_r820/visual/link_4.dae"/>
      </geometry>
    </visual>
    <collision><origin rpy="0 0 0" xyz="0.000269 -0.023503 0.058414"/><geometry><box size="0.136926 0.183015 0.252173"/></geometry></collision>
  </link>
  <link name="link_5">
    <visual>
      <origin rpy="0 0 0" xyz="0 0 0"/>
      <geometry>
        <mesh filename="C:/dev/threepp/build/_deps/threepp_data-src/urdf/lbr_iiwa_14_r820/visual/link_5.dae"/>
      </geometry>
    </visual>
    <collision><origin rpy="0 0 0" xyz="-0.000121 -0.015503 0.313087"/><geometry><box size="0.136273 0.167034 0.277175"/></geometry></collision>
  </link>
  <link name="link_6">
    <visual>
      <origin rpy="0 0 0" xyz="0 0 0"/>
      <geometry>
        <mesh filename="C:/dev/threepp/build/_deps/threepp_data-src/urdf/lbr_iiwa_14_r820/visual/link_6.dae"/>
      </geometry>
    </visual>
    <collision><origin rpy="0 0 0" xyz="-0.000066 -0.001862 -0.002791"/><geometry><box size="0.132602 0.137681 0.167384"/></geometry></collision>
  </link>
  <link name="link_7">
    <visual>
      <origin rpy="0 0 0" xyz="0 0 0"/>
      <geometry>
        <mesh filename="C:/dev/threepp/build/_deps/threepp_data-src/urdf/lbr_iiwa_14_r820/visual/link_7.dae"/>
      </geometry>
    </visual>
    <collision><origin rpy="0 0 0" xyz="-0.000001 0.000009 0.098559"/><geometry><box size="0.103694 0.103857 0.054917"/></geometry></collision>
  </link>
  <link name="tool0"/>
  <!-- end of link list -->
  <!-- joint list -->
  <joint name="joint_a1" type="revolute">
    <origin rpy="0 0 0" xyz="0 0 0"/>
    <parent link="base_link"/>
    <child link="link_1"/>
    <axis xyz="0 0 1"/>
    <limit effort="0" lower="-2.9668" upper="2.9668" velocity="1.4834"/>
  </joint>
  <joint name="joint_a2" type="revolute">
    <origin rpy="0 0 0" xyz="-0.00043624 0 0.36"/>
    <parent link="link_1"/>
    <child link="link_2"/>
    <axis xyz="0 1 0"/>
    <limit effort="0" lower="-2.0942" upper="2.0942" velocity="1.4834"/>
  </joint>
  <joint name="joint_a3" type="revolute">
    <origin rpy="0 0 0" xyz="0 0 0"/>
    <parent link="link_2"/>
    <child link="link_3"/>
    <axis xyz="0 0 1"/>
    <limit effort="0" lower="-2.9668" upper="2.9668" velocity="1.7452"/>
  </joint>
  <joint name="joint_a4" type="revolute">
    <origin rpy="0 0 0" xyz="0.00043624 0 0.42"/>
    <parent link="link_3"/>
    <child link="link_4"/>
    <axis xyz="0 -1 0"/>
    <limit effort="0" lower="-2.0942" upper="2.0942" velocity="1.3089"/>
  </joint>
  <joint name="joint_a5" type="revolute">
    <origin rpy="0 0 0" xyz="0 0 0"/>
    <parent link="link_4"/>
    <child link="link_5"/>
    <axis xyz="0 0 1"/>
    <limit effort="0" lower="-2.9668" upper="2.9668" velocity="2.2688"/>
  </joint>
  <joint name="joint_a6" type="revolute">
    <origin rpy="0 0 0" xyz="0 0 0.4"/>
    <parent link="link_5"/>
    <child link="link_6"/>
    <axis xyz="0 1 0"/>
    <limit effort="0" lower="-2.0942" upper="2.0942" velocity="2.356"/>
  </joint>
  <joint name="joint_a7" type="revolute">
    <origin rpy="0 0 0" xyz="0 0 0"/>
    <parent link="link_6"/>
    <child link="link_7"/>
    <axis xyz="0 0 1"/>
    <limit effort="0" lower="-3.0541" upper="3.0541" velocity="2.356"/>
  </joint>
  <joint name="joint_a7-tool0" type="fixed">
    <origin rpy="0 0 0" xyz="0 0 0.126"/>
    <parent link="link_7"/>
    <child link="tool0"/>
    <axis xyz="0 0 0"/>
  </joint>
  <!-- end of joint list -->
  <!-- ROS base_link to KUKA $ROBROOT coordinate system transform -->
  <link name="base"/>
  <joint name="base_link-base" type="fixed">
    <origin rpy="0 0 0" xyz="0 0 0"/>
    <parent link="base_link"/>
    <child link="base"/>
  </joint>
  <link name="finger_left">
    <visual><origin rpy="0 0 0" xyz="0 0 0"/><geometry><box size="0.012 0.03 0.085"/></geometry></visual>
    <collision><origin rpy="0 0 0" xyz="0 0 0"/><geometry><box size="0.012 0.03 0.085"/></geometry></collision>
  </link>
  <joint name="finger_left_joint" type="prismatic">
    <origin rpy="0 0 0" xyz="0.028 0 0.165"/>
    <parent link="link_7"/>
    <child link="finger_left"/>
    <axis xyz="1 0 0"/>
    <limit effort="200" lower="-0.02" upper="0.035" velocity="1.0"/>
  </joint>
  <link name="finger_right">
    <visual><origin rpy="0 0 0" xyz="0 0 0"/><geometry><box size="0.012 0.03 0.085"/></geometry></visual>
    <collision><origin rpy="0 0 0" xyz="0 0 0"/><geometry><box size="0.012 0.03 0.085"/></geometry></collision>
  </link>
  <joint name="finger_right_joint" type="prismatic">
    <origin rpy="0 0 0" xyz="-0.028 0 0.165"/>
    <parent link="link_7"/>
    <child link="finger_right"/>
    <axis xyz="-1 0 0"/>
    <limit effort="200" lower="-0.02" upper="0.035" velocity="1.0"/>
  </joint>
</robot>

